Workbook

Sheet Products0
A1: ProductID | B1: Niche | C1: ProductName | D1: Brand | E1: KeyBenefit | F1: TopFeatures | G1: IdealFor | H1: Keywords | I1: PriceBand | J1: AmazonAffiliateURL | K1: DisclosureLine | L1: Angle | M1: HookStyle | N1: TemplateID | O1: BackgroundTheme | P1: Status | Q1: LastUsedDate | R1: Priority | S1: PinTitle | T1: PinHookOverlay | U1: PinDescription | V1: BoardName | W1: CanvaImageName
K2: As an Amazon Associate I earn from qualifying purchases. #ad | S2: =IF(C2="","",C2 & " — " & IF(L2="Upgrade","Easy upgrade for ","Best pick for ") & G2) | T2: =IFERROR(__xludf.DUMMYFUNCTION("IF(C2="""","""",IF(M2=""Question"",""Still dealing with "" & LOWER(REGEXREPLACE(SPLIT(H2,"","",TRUE,TRUE),""\s+$"","""")) & ""?"", IF(M2=""Bold Claim"", ""Fix this in 5 minutes"", IF(M2=""Stop Doing This"", ""Stop struggling with this"", IF(M2=""3 Things"&""", ""3 reasons you’ll love this"", ""Best pick for "" & G2)))))"),"") | U2: =IF(C2="","","Why it’s worth it: " & E2 & " Features: " & SUBSTITUTE(F2,";"," • ") & ". Great for: " & G2 & ". Keywords: " & H2 & " " & K2) | V2: =IF(B2="","",IFERROR(VLOOKUP(B2,Boards0!A:B,2,FALSE),"General Finds")) | W2: =IF(A2="","",TEXT(TODAY(),"yyyy-mm-dd") & "_" & N2 & "_" & A2 & ".png")
K3: As an Amazon Associate I earn from qualifying purchases. #ad
K4: As an Amazon Associate I earn from qualifying purchases. #ad

Sheet Boards0
A1: Niche | B1: BoardName
A2: electronics | B2: Smart Electronics Finds
A3: home/kitchen | B3: Kitchen Upgrades & Must-Haves
A4: tools | B4: Tools That Save Time
A5: fitness | B5: Home Gym Essentials
A6: cars | B6: Car Accessories & Upgrades
A7: computer accessories | B7: Desk Setup & Accessories

Sheet Products
A1: ProductID | B1: Niche | C1: ProductName | D1: Brand | E1: KeyBenefit | F1: TopFeatures | G1: IdealFor | H1: Keywords | I1: PriceBand | J1: AmazonAffiliateURL | K1: DisclosureLine | L1: Angle | M1: HookStyle | N1: TemplateID | O1: BackgroundTheme | P1: Status | Q1: LastUsedDate | R1: Priority | S1: PinTitle | T1: PinHookOverlay | U1: PinDescription | V1: BoardName | W1: CanvaImageName
A2: PROD001 | B2: electronics | C2: Anker PowerCore 20000mAh Power Bank | D2: Anker | E2: Never run out of battery on the go with 20000mAh capacity | F2: 20000mAh capacity; Charges iPhone 5 times; Dual USB ports; Fast charging; Compact design | G2: travelers and commuters | H2: portable charger, power bank, phone charger, travel accessories, USB charger, battery pack, Anker, mobile charging | I2: mid | J2: https://www.amazon.ca/Anker-PowerCore-Essential-High-Capacity-Compatible/dp/B07SQ5MQ6K?mcid=4497651534b83e49a9dbb8d6e07fab7c&hvadid=706741198290&hvpos=&hvnetw=g&hvrand=10374663545583557608&hvpone=&hvptwo=&hvqmt=&hvdev=c&hvdvcmdl=&hvlocint=&hvlocphy=9000833&hvtargid=pla-825479559737&psc=1&hvocijid=10374663545583557608-B07SQ5MQ6K-&hvexpln=0&gad_source=1&linkCode=ll1&tag=allitechstore-20&linkId=ed124977636908a29873fd4606abe445&language=en_CA&ref_=as_li_ss_tl | K2: As an Amazon Associate I earn from qualifying purchases. #ad | L2: Problem/Solution | M2: Question | N2: T1 | O2: tech | P2: READY | R2: 5 | S2: =IF(C2="","",C2 & " — " & IF(L2="Upgrade","Easy upgrade for ","Best pick for ") & G2) -> Anker PowerCore 20000mAh Power Bank — Best pick for travelers and commuters | T2: =IFERROR(__xludf.DUMMYFUNCTION("IF(C2="""","""",IF(M2=""Question"",""Still dealing with "" & LOWER(REGEXREPLACE(SPLIT(H2,"","",TRUE,TRUE),""\s+$"","""")) & ""?"", IF(M2=""Bold Claim"", ""Fix this in 5 minutes"", IF(M2=""Stop Doing This"", ""Stop struggling with this"", IF(M2=""3 Things"&""", ""3 reasons you’ll love this"", ""Best pick for "" & G2)))))"),"Still dealing with portable charger?") -> Still dealing with portable charger? | U2: =IF(C2="","","Why it’s worth it: " & E2 & " Features: " & SUBSTITUTE(F2,";"," • ") & ". Great for: " & G2 & ". Keywords: " & H2 & " " & K2) -> Why it’s worth it: Never run out of battery on the go with 20000mAh capacity Features: 20000mAh capacity • Charges iPhone 5 times • Dual USB ports • Fast charging • Compact design. Great for: travelers and commuters. Keywords: portable charger, power bank, phone charger, travel accessories, USB charger, battery pack, Anker, mobile charging As an Amazon Associate I earn from qualifying purchases. #ad | V2: =IF(B2="","",IFERROR(VLOOKUP(B2,Boards0!A:B,2,FALSE),"General Finds")) -> Smart Electronics Finds | W2: =IF(A2="","",TEXT(TODAY(),"yyyy-mm-dd") & "_" & N2 & "_" & A2 & ".png") -> 2026-01-08_T1_PROD001.png
A3: PROD002 | B3: home/kitchen | C3: Instant Pot Duo 7-in-1 Electric Pressure Cooker | D3: Instant Pot | E3: Cook meals 70% faster with this versatile 7-in-1 appliance | F3: 7 cooking functions; 6-quart capacity; Programmable timer; Stainless steel; Energy efficient | G3: busy families and meal preppers | H3: instant pot, pressure cooker, slow cooker, rice cooker, kitchen appliances, meal prep, cooking, time saver | I3: mid | J3: https://www.amazon.com/dp/XXXXXXX?tag=yourtag-20 | K3: As an Amazon Associate I earn from qualifying purchases. #ad | L3: Upgrade | M3: Bold Claim | N3: T2 | O3: kitchen | P3: READY | R3: 4 | S3: =IF(C3="","",C3 & " — " & IF(L3="Upgrade","Easy upgrade for ","Best pick for ") & G3) -> Instant Pot Duo 7-in-1 Electric Pressure Cooker — Easy upgrade for busy families and meal preppers | T3: =IFERROR(__xludf.DUMMYFUNCTION("IF(C3="""","""",IF(M3=""Question"",""Still dealing with "" & LOWER(REGEXREPLACE(SPLIT(H3,"","",TRUE,TRUE),""\s+$"","""")) & ""?"", IF(M3=""Bold Claim"", ""Fix this in 5 minutes"", IF(M3=""Stop Doing This"", ""Stop struggling with this"", IF(M3=""3 Things"&""", ""3 reasons you’ll love this"", ""Best pick for "" & G3)))))"),"Fix this in 5 minutes") -> Fix this in 5 minutes | U3: =IF(C3="","","Why it’s worth it: " & E3 & " Features: " & SUBSTITUTE(F3,";"," • ") & ". Great for: " & G3 & ". Keywords: " & H3 & " " & K3) -> Why it’s worth it: Cook meals 70% faster with this versatile 7-in-1 appliance Features: 7 cooking functions • 6-quart capacity • Programmable timer • Stainless steel • Energy efficient. Great for: busy families and meal preppers. Keywords: instant pot, pressure cooker, slow cooker, rice cooker, kitchen appliances, meal prep, cooking, time saver As an Amazon Associate I earn from qualifying purchases. #ad | V3: =IF(B3="","",IFERROR(VLOOKUP(B3,Boards0!A:B,2,FALSE),"General Finds")) -> Kitchen Upgrades & Must-Haves | W3: =IF(A3="","",TEXT(TODAY(),"yyyy-mm-dd") & "_" & N3 & "_" & A3 & ".png") -> 2026-01-08_T2_PROD002.png
A4: PROD003 | B4: fitness | C4: Resistance Bands Set with Handles | D4: Fit Simplify | E4: Get a full-body workout anywhere with portable resistance bands | F4: 5 resistance levels; Door anchor included; Comfortable handles; Carrying bag; Exercise guide | G4: home workouts and travelers | H4: resistance bands, workout bands, exercise equipment, home gym, fitness, strength training, portable gym | I4: budget | J4: https://www.amazon.com/dp/XXXXXXX?tag=yourtag-20 | K4: As an Amazon Associate I earn from qualifying purchases. #ad | L4: Quick Tip | M4: 3 Things | N4: T3 | O4: gym | P4: READY | R4: 3 | S4: =IF(C4="","",C4 & " — " & IF(L4="Upgrade","Easy upgrade for ","Best pick for ") & G4) -> Resistance Bands Set with Handles — Best pick for home workouts and travelers | T4: =IFERROR(__xludf.DUMMYFUNCTION("IF(C4="""","""",IF(M4=""Question"",""Still dealing with "" & LOWER(REGEXREPLACE(SPLIT(H4,"","",TRUE,TRUE),""\s+$"","""")) & ""?"", IF(M4=""Bold Claim"", ""Fix this in 5 minutes"", IF(M4=""Stop Doing This"", ""Stop struggling with this"", IF(M4=""3 Things"&""", ""3 reasons you’ll love this"", ""Best pick for "" & G4)))))"),"3 reasons you’ll love this") -> 3 reasons you’ll love this | U4: =IF(C4="","","Why it’s worth it: " & E4 & " Features: " & SUBSTITUTE(F4,";"," • ") & ". Great for: " & G4 & ". Keywords: " & H4 & " " & K4) -> Why it’s worth it: Get a full-body workout anywhere with portable resistance bands Features: 5 resistance levels • Door anchor included • Comfortable handles • Carrying bag • Exercise guide. Great for: home workouts and travelers. Keywords: resistance bands, workout bands, exercise equipment, home gym, fitness, strength training, portable gym As an Amazon Associate I earn from qualifying purchases. #ad | V4: =IF(B4="","",IFERROR(VLOOKUP(B4,Boards0!A:B,2,FALSE),"General Finds")) -> Home Gym Essentials | W4: =IF(A4="","",TEXT(TODAY(),"yyyy-mm-dd") & "_" & N4 & "_" & A4 & ".png") -> 2026-01-08_T3_PROD003.png
A5: PROD004 | B5: tools | C5: DEWALT 20V MAX Cordless Drill Combo Kit | D5: DEWALT | E5: Professional-grade power tools for any DIY project | F5: 20V lithium battery; 2-speed transmission; LED work light; Compact design; Includes 2 batteries | G5: DIY enthusiasts and homeowners | H5: cordless drill, power tools, DEWALT, drill kit, home improvement, DIY tools, battery drill | I5: premium | J5: https://www.amazon.com/dp/XXXXXXX?tag=yourtag-20 | K5: As an Amazon Associate I earn from qualifying purchases. #ad | L5: Upgrade | M5: Best For | N5: T4 | O5: garage | P5: READY | R5: 4 | S5: =IF(C5="","",C5 & " — " & IF(L5="Upgrade","Easy upgrade for ","Best pick for ") & G5) -> DEWALT 20V MAX Cordless Drill Combo Kit — Easy upgrade for DIY enthusiasts and homeowners | T5: =IFERROR(__xludf.DUMMYFUNCTION("IF(C5="""","""",IF(M5=""Question"",""Still dealing with "" & LOWER(REGEXREPLACE(SPLIT(H5,"","",TRUE,TRUE),""\s+$"","""")) & ""?"", IF(M5=""Bold Claim"", ""Fix this in 5 minutes"", IF(M5=""Stop Doing This"", ""Stop struggling with this"", IF(M5=""3 Things"&""", ""3 reasons you’ll love this"", ""Best pick for "" & G5)))))"),"Best pick for DIY enthusiasts and homeowners") -> Best pick for DIY enthusiasts and homeowners | U5: =IF(C5="","","Why it’s worth it: " & E5 & " Features: " & SUBSTITUTE(F5,";"," • ") & ". Great for: " & G5 & ". Keywords: " & H5 & " " & K5) -> Why it’s worth it: Professional-grade power tools for any DIY project Features: 20V lithium battery • 2-speed transmission • LED work light • Compact design • Includes 2 batteries. Great for: DIY enthusiasts and homeowners. Keywords: cordless drill, power tools, DEWALT, drill kit, home improvement, DIY tools, battery drill As an Amazon Associate I earn from qualifying purchases. #ad | V5: =IF(B5="","",IFERROR(VLOOKUP(B5,Boards0!A:B,2,FALSE),"General Finds")) -> Tools That Save Time | W5: =IF(A5="","",TEXT(TODAY(),"yyyy-mm-dd") & "_" & N5 & "_" & A5 & ".png") -> 2026-01-08_T4_PROD004.png
A6: PROD005 | B6: cars | C6: VIOFO Dash Cam Front and Rear Camera | D6: VIOFO | E6: Protect yourself with 24/7 recording and parking mode | F6: 1080P front and rear; Night vision; G-sensor; Loop recording; 32GB SD card included | G6: daily drivers and road trippers | H6: dash cam, car camera, driving recorder, car accessories, safety, parking camera, vehicle security | I6: mid | J6: https://www.amazon.com/dp/XXXXXXX?tag=yourtag-20 | K6: As an Amazon Associate I earn from qualifying purchases. #ad | L6: Problem/Solution | M6: Stop Doing This | N6: T5 | O6: car | P6: READY | R6: 5 | S6: =IF(C6="","",C6 & " — " & IF(L6="Upgrade","Easy upgrade for ","Best pick for ") & G6) -> VIOFO Dash Cam Front and Rear Camera — Best pick for daily drivers and road trippers | T6: =IFERROR(__xludf.DUMMYFUNCTION("IF(C6="""","""",IF(M6=""Question"",""Still dealing with "" & LOWER(REGEXREPLACE(SPLIT(H6,"","",TRUE,TRUE),""\s+$"","""")) & ""?"", IF(M6=""Bold Claim"", ""Fix this in 5 minutes"", IF(M6=""Stop Doing This"", ""Stop struggling with this"", IF(M6=""3 Things"&""", ""3 reasons you’ll love this"", ""Best pick for "" & G6)))))"),"Stop struggling with this") -> Stop struggling with this | U6: =IF(C6="","","Why it’s worth it: " & E6 & " Features: " & SUBSTITUTE(F6,";"," • ") & ". Great for: " & G6 & ". Keywords: " & H6 & " " & K6) -> Why it’s worth it: Protect yourself with 24/7 recording and parking mode Features: 1080P front and rear • Night vision • G-sensor • Loop recording • 32GB SD card included. Great for: daily drivers and road trippers. Keywords: dash cam, car camera, driving recorder, car accessories, safety, parking camera, vehicle security As an Amazon Associate I earn from qualifying purchases. #ad | V6: =IF(B6="","",IFERROR(VLOOKUP(B6,Boards0!A:B,2,FALSE),"General Finds")) -> Car Accessories & Upgrades | W6: =IF(A6="","",TEXT(TODAY(),"yyyy-mm-dd") & "_" & N6 & "_" & A6 & ".png") -> 2026-01-08_T5_PROD005.png
A7: PROD006 | B7: computer accessories | C7: Logitech MX Master 3 Wireless Mouse | D7: Logitech | E7: Boost productivity with ultra-precise scrolling and customizable buttons | F7: MagSpeed scrolling; Ergonomic design; Multi-device connectivity; USB-C charging; Customizable buttons | G7: professionals and content creators | H7: wireless mouse, ergonomic mouse, Logitech, productivity, computer accessories, desk setup, office gear | I7: premium | J7: https://www.amazon.com/dp/XXXXXXX?tag=yourtag-20 | K7: As an Amazon Associate I earn from qualifying purchases. #ad | L7: Upgrade | M7: Best For | N7: T1 | O7: clean | P7: READY | R7: 4 | S7: =IF(C7="","",C7 & " — " & IF(L7="Upgrade","Easy upgrade for ","Best pick for ") & G7) -> Logitech MX Master 3 Wireless Mouse — Easy upgrade for professionals and content creators | T7: =IFERROR(__xludf.DUMMYFUNCTION("IF(C7="""","""",IF(M7=""Question"",""Still dealing with "" & LOWER(REGEXREPLACE(SPLIT(H7,"","",TRUE,TRUE),""\s+$"","""")) & ""?"", IF(M7=""Bold Claim"", ""Fix this in 5 minutes"", IF(M7=""Stop Doing This"", ""Stop struggling with this"", IF(M7=""3 Things"&""", ""3 reasons you’ll love this"", ""Best pick for "" & G7)))))"),"Best pick for professionals and content creators") -> Best pick for professionals and content creators | U7: =IF(C7="","","Why it’s worth it: " & E7 & " Features: " & SUBSTITUTE(F7,";"," • ") & ". Great for: " & G7 & ". Keywords: " & H7 & " " & K7) -> Why it’s worth it: Boost productivity with ultra-precise scrolling and customizable buttons Features: MagSpeed scrolling • Ergonomic design • Multi-device connectivity • USB-C charging • Customizable buttons. Great for: professionals and content creators. Keywords: wireless mouse, ergonomic mouse, Logitech, productivity, computer accessories, desk setup, office gear As an Amazon Associate I earn from qualifying purchases. #ad | V7: =IF(B7="","",IFERROR(VLOOKUP(B7,Boards0!A:B,2,FALSE),"General Finds")) -> Desk Setup & Accessories | W7: =IF(A7="","",TEXT(TODAY(),"yyyy-mm-dd") & "_" & N7 & "_" & A7 & ".png") -> 2026-01-08_T1_PROD006.png
A8: PROD007 | B8: electronics | C8: Apple AirPods Pro 2nd Generation | D8: Apple | E8: Experience immersive sound with active noise cancellation | F8: Active noise cancellation; Transparency mode; Spatial audio; 6-hour battery; MagSafe charging | G8: music lovers and commuters | H8: AirPods, wireless earbuds, Apple, noise cancelling, earphones, Bluetooth headphones, audio | I8: premium | J8: https://www.amazon.com/dp/XXXXXXX?tag=yourtag-20 | K8: As an Amazon Associate I earn from qualifying purchases. #ad | L8: Upgrade | M8: Question | N8: T2 | O8: tech | P8: READY | R8: 5 | S8: =IF(C8="","",C8 & " — " & IF(L8="Upgrade","Easy upgrade for ","Best pick for ") & G8) -> Apple AirPods Pro 2nd Generation — Easy upgrade for music lovers and commuters | T8: =IFERROR(__xludf.DUMMYFUNCTION("IF(C8="""","""",IF(M8=""Question"",""Still dealing with "" & LOWER(REGEXREPLACE(SPLIT(H8,"","",TRUE,TRUE),""\s+$"","""")) & ""?"", IF(M8=""Bold Claim"", ""Fix this in 5 minutes"", IF(M8=""Stop Doing This"", ""Stop struggling with this"", IF(M8=""3 Things"&""", ""3 reasons you’ll love this"", ""Best pick for "" & G8)))))"),"Still dealing with airpods?") -> Still dealing with airpods? | U8: =IF(C8="","","Why it’s worth it: " & E8 & " Features: " & SUBSTITUTE(F8,";"," • ") & ". Great for: " & G8 & ". Keywords: " & H8 & " " & K8) -> Why it’s worth it: Experience immersive sound with active noise cancellation Features: Active noise cancellation • Transparency mode • Spatial audio • 6-hour battery • MagSafe charging. Great for: music lovers and commuters. Keywords: AirPods, wireless earbuds, Apple, noise cancelling, earphones, Bluetooth headphones, audio As an Amazon Associate I earn from qualifying purchases. #ad | V8: =IF(B8="","",IFERROR(VLOOKUP(B8,Boards0!A:B,2,FALSE),"General Finds")) -> Smart Electronics Finds | W8: =IF(A8="","",TEXT(TODAY(),"yyyy-mm-dd") & "_" & N8 & "_" & A8 & ".png") -> 2026-01-08_T2_PROD007.png
A9: PROD008 | B9: home/kitchen | C9: Ninja Air Fryer 4-Quart | D9: Ninja | E9: Enjoy crispy fried foods with 75% less fat | F9: 4-quart capacity; 400°F max temp; Easy to clean; Dishwasher safe; Compact design | G9: health-conscious cooks and small families | H9: air fryer, Ninja, healthy cooking, kitchen appliances, oil-free fryer, countertop cooker | I9: mid | J9: https://www.amazon.com/dp/XXXXXXX?tag=yourtag-20 | K9: As an Amazon Associate I earn from qualifying purchases. #ad | L9: Problem/Solution | M9: Bold Claim | N9: T3 | O9: kitchen | P9: READY | R9: 4 | S9: =IF(C9="","",C9 & " — " & IF(L9="Upgrade","Easy upgrade for ","Best pick for ") & G9) -> Ninja Air Fryer 4-Quart — Best pick for health-conscious cooks and small families | T9: =IFERROR(__xludf.DUMMYFUNCTION("IF(C9="""","""",IF(M9=""Question"",""Still dealing with "" & LOWER(REGEXREPLACE(SPLIT(H9,"","",TRUE,TRUE),""\s+$"","""")) & ""?"", IF(M9=""Bold Claim"", ""Fix this in 5 minutes"", IF(M9=""Stop Doing This"", ""Stop struggling with this"", IF(M9=""3 Things"&""", ""3 reasons you’ll love this"", ""Best pick for "" & G9)))))"),"Fix this in 5 minutes") -> Fix this in 5 minutes | U9: =IF(C9="","","Why it’s worth it: " & E9 & " Features: " & SUBSTITUTE(F9,";"," • ") & ". Great for: " & G9 & ". Keywords: " & H9 & " " & K9) -> Why it’s worth it: Enjoy crispy fried foods with 75% less fat Features: 4-quart capacity • 400°F max temp • Easy to clean • Dishwasher safe • Compact design. Great for: health-conscious cooks and small families. Keywords: air fryer, Ninja, healthy cooking, kitchen appliances, oil-free fryer, countertop cooker As an Amazon Associate I earn from qualifying purchases. #ad | V9: =IF(B9="","",IFERROR(VLOOKUP(B9,Boards0!A:B,2,FALSE),"General Finds")) -> Kitchen Upgrades & Must-Haves | W9: =IF(A9="","",TEXT(TODAY(),"yyyy-mm-dd") & "_" & N9 & "_" & A9 & ".png") -> 2026-01-08_T3_PROD008.png
A10: PROD009 | B10: fitness | C10: Fitbit Charge 6 Fitness Tracker | D10: Fitbit | E10: Track your health 24/7 with advanced fitness metrics | F10: Heart rate monitor; Sleep tracking; GPS; 7-day battery; Water resistant; Stress management | G10: fitness enthusiasts and health trackers | H10: Fitbit, fitness tracker, smartwatch, health monitor, activity tracker, step counter, heart rate | I10: mid | J10: https://www.amazon.com/dp/XXXXXXX?tag=yourtag-20 | K10: As an Amazon Associate I earn from qualifying purchases. #ad | L10: Upgrade | M10: 3 Things | N10: T4 | O10: gym | P10: READY | R10: 3 | S10: =IF(C10="","",C10 & " — " & IF(L10="Upgrade","Easy upgrade for ","Best pick for ") & G10) -> Fitbit Charge 6 Fitness Tracker — Easy upgrade for fitness enthusiasts and health trackers | T10: =IFERROR(__xludf.DUMMYFUNCTION("IF(C10="""","""",IF(M10=""Question"",""Still dealing with "" & LOWER(REGEXREPLACE(SPLIT(H10,"","",TRUE,TRUE),""\s+$"","""")) & ""?"", IF(M10=""Bold Claim"", ""Fix this in 5 minutes"", IF(M10=""Stop Doing This"", ""Stop struggling with this"", IF(M10=""3 T"&"hings"", ""3 reasons you’ll love this"", ""Best pick for "" & G10)))))"),"3 reasons you’ll love this") -> 3 reasons you’ll love this | U10: =IF(C10="","","Why it’s worth it: " & E10 & " Features: " & SUBSTITUTE(F10,";"," • ") & ". Great for: " & G10 & ". Keywords: " & H10 & " " & K10) -> Why it’s worth it: Track your health 24/7 with advanced fitness metrics Features: Heart rate monitor • Sleep tracking • GPS • 7-day battery • Water resistant • Stress management. Great for: fitness enthusiasts and health trackers. Keywords: Fitbit, fitness tracker, smartwatch, health monitor, activity tracker, step counter, heart rate As an Amazon Associate I earn from qualifying purchases. #ad | V10: =IF(B10="","",IFERROR(VLOOKUP(B10,Boards0!A:B,2,FALSE),"General Finds")) -> Home Gym Essentials | W10: =IF(A10="","",TEXT(TODAY(),"yyyy-mm-dd") & "_" & N10 & "_" & A10 & ".png") -> 2026-01-08_T4_PROD009.png
A11: PROD010 | B11: tools | C11: BLACK+DECKER 20V MAX Cordless Drill | D11: BLACK+DECKER | E11: Tackle home projects with this reliable cordless drill | F11: 20V MAX battery; 11-position clutch; LED work light; Compact; Includes battery and charger | G11: homeowners and DIYers | H11: cordless drill, BLACK+DECKER, power drill, home tools, battery drill, DIY, home improvement | I11: budget | J11: https://www.amazon.com/dp/XXXXXXX?tag=yourtag-20 | K11: As an Amazon Associate I earn from qualifying purchases. #ad | L11: Quick Tip | M11: Best For | N11: T5 | O11: garage | P11: READY | R11: 3 | S11: =IF(C11="","",C11 & " — " & IF(L11="Upgrade","Easy upgrade for ","Best pick for ") & G11) -> BLACK+DECKER 20V MAX Cordless Drill — Best pick for homeowners and DIYers | T11: =IFERROR(__xludf.DUMMYFUNCTION("IF(C11="""","""",IF(M11=""Question"",""Still dealing with "" & LOWER(REGEXREPLACE(SPLIT(H11,"","",TRUE,TRUE),""\s+$"","""")) & ""?"", IF(M11=""Bold Claim"", ""Fix this in 5 minutes"", IF(M11=""Stop Doing This"", ""Stop struggling with this"", IF(M11=""3 T"&"hings"", ""3 reasons you’ll love this"", ""Best pick for "" & G11)))))"),"Best pick for homeowners and DIYers") -> Best pick for homeowners and DIYers | U11: =IF(C11="","","Why it’s worth it: " & E11 & " Features: " & SUBSTITUTE(F11,";"," • ") & ". Great for: " & G11 & ". Keywords: " & H11 & " " & K11) -> Why it’s worth it: Tackle home projects with this reliable cordless drill Features: 20V MAX battery • 11-position clutch • LED work light • Compact • Includes battery and charger. Great for: homeowners and DIYers. Keywords: cordless drill, BLACK+DECKER, power drill, home tools, battery drill, DIY, home improvement As an Amazon Associate I earn from qualifying purchases. #ad | V11: =IF(B11="","",IFERROR(VLOOKUP(B11,Boards0!A:B,2,FALSE),"General Finds")) -> Tools That Save Time | W11: =IF(A11="","",TEXT(TODAY(),"yyyy-mm-dd") & "_" & N11 & "_" & A11 & ".png") -> 2026-01-08_T5_PROD010.png
A12: PROD011 | B12: cars | C12: WeatherTech All-Weather Floor Mats | D12: WeatherTech | E12: Keep your car interior pristine with custom-fit floor mats | F12: Custom fit; All-weather protection; Easy to clean; Raised edges; Made in USA | G12: car owners and detailing enthusiasts | H12: floor mats, car mats, WeatherTech, auto accessories, car interior, all-weather mats, vehicle protection | I12: mid | J12: https://www.amazon.com/dp/XXXXXXX?tag=yourtag-20 | K12: As an Amazon Associate I earn from qualifying purchases. #ad | L12: Problem/Solution | M12: Question | N12: T1 | O12: car | P12: READY | R12: 4 | S12: =IF(C12="","",C12 & " — " & IF(L12="Upgrade","Easy upgrade for ","Best pick for ") & G12) -> WeatherTech All-Weather Floor Mats — Best pick for car owners and detailing enthusiasts | T12: =IFERROR(__xludf.DUMMYFUNCTION("IF(C12="""","""",IF(M12=""Question"",""Still dealing with "" & LOWER(REGEXREPLACE(SPLIT(H12,"","",TRUE,TRUE),""\s+$"","""")) & ""?"", IF(M12=""Bold Claim"", ""Fix this in 5 minutes"", IF(M12=""Stop Doing This"", ""Stop struggling with this"", IF(M12=""3 T"&"hings"", ""3 reasons you’ll love this"", ""Best pick for "" & G12)))))"),"Still dealing with floor mats?") -> Still dealing with floor mats? | U12: =IF(C12="","","Why it’s worth it: " & E12 & " Features: " & SUBSTITUTE(F12,";"," • ") & ". Great for: " & G12 & ". Keywords: " & H12 & " " & K12) -> Why it’s worth it: Keep your car interior pristine with custom-fit floor mats Features: Custom fit • All-weather protection • Easy to clean • Raised edges • Made in USA. Great for: car owners and detailing enthusiasts. Keywords: floor mats, car mats, WeatherTech, auto accessories, car interior, all-weather mats, vehicle protection As an Amazon Associate I earn from qualifying purchases. #ad | V12: =IF(B12="","",IFERROR(VLOOKUP(B12,Boards0!A:B,2,FALSE),"General Finds")) -> Car Accessories & Upgrades | W12: =IF(A12="","",TEXT(TODAY(),"yyyy-mm-dd") & "_" & N12 & "_" & A12 & ".png") -> 2026-01-08_T1_PROD011.png
A13: PROD012 | B13: computer accessories | C13: Mechanical Keyboard RGB Backlit | D13: Redragon | E13: Enhance your typing experience with tactile mechanical switches | F13: RGB backlight; Mechanical switches; Anti-ghosting; Ergonomic; Durable construction | G13: gamers and typists | H13: mechanical keyboard, gaming keyboard, RGB keyboard, Redragon, computer accessories, backlit keyboard | I13: budget | J13: https://www.amazon.com/dp/XXXXXXX?tag=yourtag-20 | K13: As an Amazon Associate I earn from qualifying purchases. #ad | L13: Upgrade | M13: Bold Claim | N13: T2 | O13: clean | P13: READY | R13: 3 | S13: =IF(C13="","",C13 & " — " & IF(L13="Upgrade","Easy upgrade for ","Best pick for ") & G13) -> Mechanical Keyboard RGB Backlit — Easy upgrade for gamers and typists | T13: =IFERROR(__xludf.DUMMYFUNCTION("IF(C13="""","""",IF(M13=""Question"",""Still dealing with "" & LOWER(REGEXREPLACE(SPLIT(H13,"","",TRUE,TRUE),""\s+$"","""")) & ""?"", IF(M13=""Bold Claim"", ""Fix this in 5 minutes"", IF(M13=""Stop Doing This"", ""Stop struggling with this"", IF(M13=""3 T"&"hings"", ""3 reasons you’ll love this"", ""Best pick for "" & G13)))))"),"Fix this in 5 minutes") -> Fix this in 5 minutes | U13: =IF(C13="","","Why it’s worth it: " & E13 & " Features: " & SUBSTITUTE(F13,";"," • ") & ". Great for: " & G13 & ". Keywords: " & H13 & " " & K13) -> Why it’s worth it: Enhance your typing experience with tactile mechanical switches Features: RGB backlight • Mechanical switches • Anti-ghosting • Ergonomic • Durable construction. Great for: gamers and typists. Keywords: mechanical keyboard, gaming keyboard, RGB keyboard, Redragon, computer accessories, backlit keyboard As an Amazon Associate I earn from qualifying purchases. #ad | V13: =IF(B13="","",IFERROR(VLOOKUP(B13,Boards0!A:B,2,FALSE),"General Finds")) -> Desk Setup & Accessories | W13: =IF(A13="","",TEXT(TODAY(),"yyyy-mm-dd") & "_" & N13 & "_" & A13 & ".png") -> 2026-01-08_T2_PROD012.png
A14: PROD013 | B14: electronics | C14: Samsung 65-Inch 4K Smart TV | D14: Samsung | E14: Transform your living room with stunning 4K picture quality | F14: 65-inch 4K display; Smart TV features; HDR support; Voice control; Multiple HDMI ports | G14: home entertainment enthusiasts | H14: 4K TV, Samsung TV, smart TV, large screen TV, home theater, streaming TV, entertainment | I14: premium | J14: https://www.amazon.com/dp/XXXXXXX?tag=yourtag-20 | K14: As an Amazon Associate I earn from qualifying purchases. #ad | L14: Upgrade | M14: Question | N14: T3 | O14: tech | P14: READY | R14: 5 | S14: =IF(C14="","",C14 & " — " & IF(L14="Upgrade","Easy upgrade for ","Best pick for ") & G14) -> Samsung 65-Inch 4K Smart TV — Easy upgrade for home entertainment enthusiasts | T14: =IFERROR(__xludf.DUMMYFUNCTION("IF(C14="""","""",IF(M14=""Question"",""Still dealing with "" & LOWER(REGEXREPLACE(SPLIT(H14,"","",TRUE,TRUE),""\s+$"","""")) & ""?"", IF(M14=""Bold Claim"", ""Fix this in 5 minutes"", IF(M14=""Stop Doing This"", ""Stop struggling with this"", IF(M14=""3 T"&"hings"", ""3 reasons you’ll love this"", ""Best pick for "" & G14)))))"),"Still dealing with 4k tv?") -> Still dealing with 4k tv? | U14: =IF(C14="","","Why it’s worth it: " & E14 & " Features: " & SUBSTITUTE(F14,";"," • ") & ". Great for: " & G14 & ". Keywords: " & H14 & " " & K14) -> Why it’s worth it: Transform your living room with stunning 4K picture quality Features: 65-inch 4K display • Smart TV features • HDR support • Voice control • Multiple HDMI ports. Great for: home entertainment enthusiasts. Keywords: 4K TV, Samsung TV, smart TV, large screen TV, home theater, streaming TV, entertainment As an Amazon Associate I earn from qualifying purchases. #ad | V14: =IF(B14="","",IFERROR(VLOOKUP(B14,Boards0!A:B,2,FALSE),"General Finds")) -> Smart Electronics Finds | W14: =IF(A14="","",TEXT(TODAY(),"yyyy-mm-dd") & "_" & N14 & "_" & A14 & ".png") -> 2026-01-08_T3_PROD013.png
A15: PROD014 | B15: home/kitchen | C15: Keurig K-Elite Coffee Maker | D15: Keurig | E15: Brew perfect coffee in under a minute with one-touch convenience | F15: 5 cup sizes; Iced coffee setting; Strong brew option; Large water reservoir; Programmable | G15: coffee lovers and busy professionals | H15: Keurig, coffee maker, single serve, K-cup, coffee machine, brewing system, kitchen appliances | I15: mid | J15: https://www.amazon.com/dp/XXXXXXX?tag=yourtag-20 | K15: As an Amazon Associate I earn from qualifying purchases. #ad | L15: Quick Tip | M15: 3 Things | N15: T4 | O15: kitchen | P15: READY | R15: 4 | S15: =IF(C15="","",C15 & " — " & IF(L15="Upgrade","Easy upgrade for ","Best pick for ") & G15) -> Keurig K-Elite Coffee Maker — Best pick for coffee lovers and busy professionals | T15: =IFERROR(__xludf.DUMMYFUNCTION("IF(C15="""","""",IF(M15=""Question"",""Still dealing with "" & LOWER(REGEXREPLACE(SPLIT(H15,"","",TRUE,TRUE),""\s+$"","""")) & ""?"", IF(M15=""Bold Claim"", ""Fix this in 5 minutes"", IF(M15=""Stop Doing This"", ""Stop struggling with this"", IF(M15=""3 T"&"hings"", ""3 reasons you’ll love this"", ""Best pick for "" & G15)))))"),"3 reasons you’ll love this") -> 3 reasons you’ll love this | U15: =IF(C15="","","Why it’s worth it: " & E15 & " Features: " & SUBSTITUTE(F15,";"," • ") & ". Great for: " & G15 & ". Keywords: " & H15 & " " & K15) -> Why it’s worth it: Brew perfect coffee in under a minute with one-touch convenience Features: 5 cup sizes • Iced coffee setting • Strong brew option • Large water reservoir • Programmable. Great for: coffee lovers and busy professionals. Keywords: Keurig, coffee maker, single serve, K-cup, coffee machine, brewing system, kitchen appliances As an Amazon Associate I earn from qualifying purchases. #ad | V15: =IF(B15="","",IFERROR(VLOOKUP(B15,Boards0!A:B,2,FALSE),"General Finds")) -> Kitchen Upgrades & Must-Haves | W15: =IF(A15="","",TEXT(TODAY(),"yyyy-mm-dd") & "_" & N15 & "_" & A15 & ".png") -> 2026-01-08_T4_PROD014.png
A16: PROD015 | B16: fitness | C16: Yoga Mat Extra Thick Non-Slip | D16: BalanceFrom | E16: Practice yoga comfortably with extra cushioning and grip | F16: Extra thick 1/2 inch; Non-slip surface; Moisture resistant; Carrying strap; Easy to clean | G16: yoga practitioners and fitness enthusiasts | H16: yoga mat, exercise mat, fitness mat, yoga accessories, workout mat, non-slip mat, thick mat | I16: budget | J16: https://www.amazon.com/dp/XXXXXXX?tag=yourtag-20 | K16: As an Amazon Associate I earn from qualifying purchases. #ad | L16: Problem/Solution | M16: Stop Doing This | N16: T5 | O16: gym | P16: READY | R16: 3 | S16: =IF(C16="","",C16 & " — " & IF(L16="Upgrade","Easy upgrade for ","Best pick for ") & G16) -> Yoga Mat Extra Thick Non-Slip — Best pick for yoga practitioners and fitness enthusiasts | T16: =IFERROR(__xludf.DUMMYFUNCTION("IF(C16="""","""",IF(M16=""Question"",""Still dealing with "" & LOWER(REGEXREPLACE(SPLIT(H16,"","",TRUE,TRUE),""\s+$"","""")) & ""?"", IF(M16=""Bold Claim"", ""Fix this in 5 minutes"", IF(M16=""Stop Doing This"", ""Stop struggling with this"", IF(M16=""3 T"&"hings"", ""3 reasons you’ll love this"", ""Best pick for "" & G16)))))"),"Stop struggling with this") -> Stop struggling with this | U16: =IF(C16="","","Why it’s worth it: " & E16 & " Features: " & SUBSTITUTE(F16,";"," • ") & ". Great for: " & G16 & ". Keywords: " & H16 & " " & K16) -> Why it’s worth it: Practice yoga comfortably with extra cushioning and grip Features: Extra thick 1/2 inch • Non-slip surface • Moisture resistant • Carrying strap • Easy to clean. Great for: yoga practitioners and fitness enthusiasts. Keywords: yoga mat, exercise mat, fitness mat, yoga accessories, workout mat, non-slip mat, thick mat As an Amazon Associate I earn from qualifying purchases. #ad | V16: =IF(B16="","",IFERROR(VLOOKUP(B16,Boards0!A:B,2,FALSE),"General Finds")) -> Home Gym Essentials | W16: =IF(A16="","",TEXT(TODAY(),"yyyy-mm-dd") & "_" & N16 & "_" & A16 & ".png") -> 2026-01-08_T5_PROD015.png
A17: PROD016 | B17: tools | C17: Craftsman 230-Piece Mechanics Tool Set | D17: Craftsman | E17: Complete your workshop with this comprehensive tool set | F17: 230 pieces; Sockets and wrenches; Durable case; Chrome finish; Lifetime warranty | G17: mechanics and tool collectors | H17: tool set, Craftsman, mechanics tools, socket set, wrench set, garage tools, hand tools | I17: mid | J17: https://www.amazon.com/dp/XXXXXXX?tag=yourtag-20 | K17: As an Amazon Associate I earn from qualifying purchases. #ad | L17: Upgrade | M17: Best For | N17: T1 | O17: garage | P17: READY | R17: 4 | S17: =IF(C17="","",C17 & " — " & IF(L17="Upgrade","Easy upgrade for ","Best pick for ") & G17) -> Craftsman 230-Piece Mechanics Tool Set — Easy upgrade for mechanics and tool collectors | T17: =IFERROR(__xludf.DUMMYFUNCTION("IF(C17="""","""",IF(M17=""Question"",""Still dealing with "" & LOWER(REGEXREPLACE(SPLIT(H17,"","",TRUE,TRUE),""\s+$"","""")) & ""?"", IF(M17=""Bold Claim"", ""Fix this in 5 minutes"", IF(M17=""Stop Doing This"", ""Stop struggling with this"", IF(M17=""3 T"&"hings"", ""3 reasons you’ll love this"", ""Best pick for "" & G17)))))"),"Best pick for mechanics and tool collectors") -> Best pick for mechanics and tool collectors | U17: =IF(C17="","","Why it’s worth it: " & E17 & " Features: " & SUBSTITUTE(F17,";"," • ") & ". Great for: " & G17 & ". Keywords: " & H17 & " " & K17) -> Why it’s worth it: Complete your workshop with this comprehensive tool set Features: 230 pieces • Sockets and wrenches • Durable case • Chrome finish • Lifetime warranty. Great for: mechanics and tool collectors. Keywords: tool set, Craftsman, mechanics tools, socket set, wrench set, garage tools, hand tools As an Amazon Associate I earn from qualifying purchases. #ad | V17: =IF(B17="","",IFERROR(VLOOKUP(B17,Boards0!A:B,2,FALSE),"General Finds")) -> Tools That Save Time | W17: =IF(A17="","",TEXT(TODAY(),"yyyy-mm-dd") & "_" & N17 & "_" & A17 & ".png") -> 2026-01-08_T1_PROD016.png
A18: PROD017 | B18: cars | C18: Garmin DriveSmart 65 GPS Navigator | D18: Garmin | E18: Navigate with confidence using voice-activated GPS | F18: 6.95-inch display; Voice control; Live traffic; Bluetooth; Driver alerts; Lifetime maps | G18: road trippers and daily commuters | H18: GPS, Garmin, car navigation, GPS navigator, driving directions, car electronics, travel | I18: mid | J18: https://www.amazon.com/dp/XXXXXXX?tag=yourtag-20 | K18: As an Amazon Associate I earn from qualifying purchases. #ad | L18: Quick Tip | M18: Question | N18: T2 | O18: car | P18: READY | R18: 3 | S18: =IF(C18="","",C18 & " — " & IF(L18="Upgrade","Easy upgrade for ","Best pick for ") & G18) -> Garmin DriveSmart 65 GPS Navigator — Best pick for road trippers and daily commuters | T18: =IFERROR(__xludf.DUMMYFUNCTION("IF(C18="""","""",IF(M18=""Question"",""Still dealing with "" & LOWER(REGEXREPLACE(SPLIT(H18,"","",TRUE,TRUE),""\s+$"","""")) & ""?"", IF(M18=""Bold Claim"", ""Fix this in 5 minutes"", IF(M18=""Stop Doing This"", ""Stop struggling with this"", IF(M18=""3 T"&"hings"", ""3 reasons you’ll love this"", ""Best pick for "" & G18)))))"),"Still dealing with gps?") -> Still dealing with gps? | U18: =IF(C18="","","Why it’s worth it: " & E18 & " Features: " & SUBSTITUTE(F18,";"," • ") & ". Great for: " & G18 & ". Keywords: " & H18 & " " & K18) -> Why it’s worth it: Navigate with confidence using voice-activated GPS Features: 6.95-inch display • Voice control • Live traffic • Bluetooth • Driver alerts • Lifetime maps. Great for: road trippers and daily commuters. Keywords: GPS, Garmin, car navigation, GPS navigator, driving directions, car electronics, travel As an Amazon Associate I earn from qualifying purchases. #ad | V18: =IF(B18="","",IFERROR(VLOOKUP(B18,Boards0!A:B,2,FALSE),"General Finds")) -> Car Accessories & Upgrades | W18: =IF(A18="","",TEXT(TODAY(),"yyyy-mm-dd") & "_" & N18 & "_" & A18 & ".png") -> 2026-01-08_T2_PROD017.png
A19: PROD018 | B19: computer accessories | C19: USB-C Hub 7-in-1 Adapter | D19: Anker | E19: Expand your laptop connectivity with 7 essential ports | F19: 7 ports; 4K HDMI; USB 3.0; SD card reader; 100W power delivery; Compact design | G19: laptop users and professionals | H19: USB-C hub, laptop adapter, Anker, USB hub, HDMI adapter, computer accessories, docking station | I19: budget | J19: https://www.amazon.com/dp/XXXXXXX?tag=yourtag-20 | K19: As an Amazon Associate I earn from qualifying purchases. #ad | L19: Problem/Solution | M19: Bold Claim | N19: T3 | O19: clean | P19: READY | R19: 4 | S19: =IF(C19="","",C19 & " — " & IF(L19="Upgrade","Easy upgrade for ","Best pick for ") & G19) -> USB-C Hub 7-in-1 Adapter — Best pick for laptop users and professionals | T19: =IFERROR(__xludf.DUMMYFUNCTION("IF(C19="""","""",IF(M19=""Question"",""Still dealing with "" & LOWER(REGEXREPLACE(SPLIT(H19,"","",TRUE,TRUE),""\s+$"","""")) & ""?"", IF(M19=""Bold Claim"", ""Fix this in 5 minutes"", IF(M19=""Stop Doing This"", ""Stop struggling with this"", IF(M19=""3 T"&"hings"", ""3 reasons you’ll love this"", ""Best pick for "" & G19)))))"),"Fix this in 5 minutes") -> Fix this in 5 minutes | U19: =IF(C19="","","Why it’s worth it: " & E19 & " Features: " & SUBSTITUTE(F19,";"," • ") & ". Great for: " & G19 & ". Keywords: " & H19 & " " & K19) -> Why it’s worth it: Expand your laptop connectivity with 7 essential ports Features: 7 ports • 4K HDMI • USB 3.0 • SD card reader • 100W power delivery • Compact design. Great for: laptop users and professionals. Keywords: USB-C hub, laptop adapter, Anker, USB hub, HDMI adapter, computer accessories, docking station As an Amazon Associate I earn from qualifying purchases. #ad | V19: =IF(B19="","",IFERROR(VLOOKUP(B19,Boards0!A:B,2,FALSE),"General Finds")) -> Desk Setup & Accessories | W19: =IF(A19="","",TEXT(TODAY(),"yyyy-mm-dd") & "_" & N19 & "_" & A19 & ".png") -> 2026-01-08_T3_PROD018.png
A20: PROD019 | B20: electronics | C20: Bose QuietComfort 45 Headphones | D20: Bose | E20: Immerse yourself in music with world-class noise cancellation | F20: Active noise cancellation; 24-hour battery; Bluetooth 5.1; Comfortable design; Premium audio | G20: audiophiles and travelers | H20: Bose headphones, noise cancelling headphones, wireless headphones, Bluetooth headphones, premium audio | I20: premium | J20: https://www.amazon.com/dp/XXXXXXX?tag=yourtag-20 | K20: As an Amazon Associate I earn from qualifying purchases. #ad | L20: Upgrade | M20: 3 Things | N20: T4 | O20: tech | P20: READY | R20: 5 | S20: =IF(C20="","",C20 & " — " & IF(L20="Upgrade","Easy upgrade for ","Best pick for ") & G20) -> Bose QuietComfort 45 Headphones — Easy upgrade for audiophiles and travelers | T20: =IFERROR(__xludf.DUMMYFUNCTION("IF(C20="""","""",IF(M20=""Question"",""Still dealing with "" & LOWER(REGEXREPLACE(SPLIT(H20,"","",TRUE,TRUE),""\s+$"","""")) & ""?"", IF(M20=""Bold Claim"", ""Fix this in 5 minutes"", IF(M20=""Stop Doing This"", ""Stop struggling with this"", IF(M20=""3 T"&"hings"", ""3 reasons you’ll love this"", ""Best pick for "" & G20)))))"),"3 reasons you’ll love this") -> 3 reasons you’ll love this | U20: =IF(C20="","","Why it’s worth it: " & E20 & " Features: " & SUBSTITUTE(F20,";"," • ") & ". Great for: " & G20 & ". Keywords: " & H20 & " " & K20) -> Why it’s worth it: Immerse yourself in music with world-class noise cancellation Features: Active noise cancellation • 24-hour battery • Bluetooth 5.1 • Comfortable design • Premium audio. Great for: audiophiles and travelers. Keywords: Bose headphones, noise cancelling headphones, wireless headphones, Bluetooth headphones, premium audio As an Amazon Associate I earn from qualifying purchases. #ad | V20: =IF(B20="","",IFERROR(VLOOKUP(B20,Boards0!A:B,2,FALSE),"General Finds")) -> Smart Electronics Finds | W20: =IF(A20="","",TEXT(TODAY(),"yyyy-mm-dd") & "_" & N20 & "_" & A20 & ".png") -> 2026-01-08_T4_PROD019.png
A21: PROD020 | B21: home/kitchen | C21: Vitamix E310 Explorian Blender | D21: Vitamix | E21: Blend anything from smoothies to hot soups with professional power | F21: Variable speed control; 48-ounce container; Self-cleaning; Aircraft-grade blades; 5-year warranty | G21: health enthusiasts and home chefs | H21: Vitamix, blender, high-power blender, smoothie maker, kitchen appliances, food processor | I21: premium | J21: https://www.amazon.com/dp/XXXXXXX?tag=yourtag-20 | K21: As an Amazon Associate I earn from qualifying purchases. #ad | L21: Upgrade | M21: Stop Doing This | N21: T5 | O21: kitchen | P21: READY | R21: 4 | S21: =IF(C21="","",C21 & " — " & IF(L21="Upgrade","Easy upgrade for ","Best pick for ") & G21) -> Vitamix E310 Explorian Blender — Easy upgrade for health enthusiasts and home chefs | T21: =IFERROR(__xludf.DUMMYFUNCTION("IF(C21="""","""",IF(M21=""Question"",""Still dealing with "" & LOWER(REGEXREPLACE(SPLIT(H21,"","",TRUE,TRUE),""\s+$"","""")) & ""?"", IF(M21=""Bold Claim"", ""Fix this in 5 minutes"", IF(M21=""Stop Doing This"", ""Stop struggling with this"", IF(M21=""3 T"&"hings"", ""3 reasons you’ll love this"", ""Best pick for "" & G21)))))"),"Stop struggling with this") -> Stop struggling with this | U21: =IF(C21="","","Why it’s worth it: " & E21 & " Features: " & SUBSTITUTE(F21,";"," • ") & ". Great for: " & G21 & ". Keywords: " & H21 & " " & K21) -> Why it’s worth it: Blend anything from smoothies to hot soups with professional power Features: Variable speed control • 48-ounce container • Self-cleaning • Aircraft-grade blades • 5-year warranty. Great for: health enthusiasts and home chefs. Keywords: Vitamix, blender, high-power blender, smoothie maker, kitchen appliances, food processor As an Amazon Associate I earn from qualifying purchases. #ad | V21: =IF(B21="","",IFERROR(VLOOKUP(B21,Boards0!A:B,2,FALSE),"General Finds")) -> Kitchen Upgrades & Must-Haves | W21: =IF(A21="","",TEXT(TODAY(),"yyyy-mm-dd") & "_" & N21 & "_" & A21 & ".png") -> 2026-01-08_T5_PROD020.png
A22: PROD021 | B22: fitness | C22: Bowflex SelectTech Adjustable Dumbbells | D22: Bowflex | E22: Replace 15 sets of weights with one compact dumbbell system | F22: Adjustable 5-52.5 lbs; Space-saving; Durable construction; Easy weight selection; Compact storage | G22: home gym builders and strength trainers | H22: adjustable dumbbells, Bowflex, home gym, weights, strength training, fitness equipment, dumbbells | I22: premium | J22: https://www.amazon.com/dp/XXXXXXX?tag=yourtag-20 | K22: As an Amazon Associate I earn from qualifying purchases. #ad | L22: Problem/Solution | M22: Best For | N22: T1 | O22: gym | P22: READY | R22: 5 | S22: =IF(C22="","",C22 & " — " & IF(L22="Upgrade","Easy upgrade for ","Best pick for ") & G22) -> Bowflex SelectTech Adjustable Dumbbells — Best pick for home gym builders and strength trainers | T22: =IFERROR(__xludf.DUMMYFUNCTION("IF(C22="""","""",IF(M22=""Question"",""Still dealing with "" & LOWER(REGEXREPLACE(SPLIT(H22,"","",TRUE,TRUE),""\s+$"","""")) & ""?"", IF(M22=""Bold Claim"", ""Fix this in 5 minutes"", IF(M22=""Stop Doing This"", ""Stop struggling with this"", IF(M22=""3 T"&"hings"", ""3 reasons you’ll love this"", ""Best pick for "" & G22)))))"),"Best pick for home gym builders and strength trainers") -> Best pick for home gym builders and strength trainers | U22: =IF(C22="","","Why it’s worth it: " & E22 & " Features: " & SUBSTITUTE(F22,";"," • ") & ". Great for: " & G22 & ". Keywords: " & H22 & " " & K22) -> Why it’s worth it: Replace 15 sets of weights with one compact dumbbell system Features: Adjustable 5-52.5 lbs • Space-saving • Durable construction • Easy weight selection • Compact storage. Great for: home gym builders and strength trainers. Keywords: adjustable dumbbells, Bowflex, home gym, weights, strength training, fitness equipment, dumbbells As an Amazon Associate I earn from qualifying purchases. #ad | V22: =IF(B22="","",IFERROR(VLOOKUP(B22,Boards0!A:B,2,FALSE),"General Finds")) -> Home Gym Essentials | W22: =IF(A22="","",TEXT(TODAY(),"yyyy-mm-dd") & "_" & N22 & "_" & A22 & ".png") -> 2026-01-08_T1_PROD021.png
A23: PROD022 | B23: tools | C23: Bosch 12V Cordless Drill Driver Kit | D23: Bosch | E23: Handle precision tasks with this compact cordless drill | F23: 12V battery; Compact design; 20-position clutch; LED light; Includes 2 batteries | G23: precision work and tight spaces | H23: Bosch drill, cordless drill, compact drill, 12V drill, power tools, precision tools | I23: mid | J23: https://www.amazon.com/dp/XXXXXXX?tag=yourtag-20 | K23: As an Amazon Associate I earn from qualifying purchases. #ad | L23: Quick Tip | M23: Question | N23: T2 | O23: garage | P23: READY | R23: 3 | S23: =IF(C23="","",C23 & " — " & IF(L23="Upgrade","Easy upgrade for ","Best pick for ") & G23) -> Bosch 12V Cordless Drill Driver Kit — Best pick for precision work and tight spaces | T23: =IFERROR(__xludf.DUMMYFUNCTION("IF(C23="""","""",IF(M23=""Question"",""Still dealing with "" & LOWER(REGEXREPLACE(SPLIT(H23,"","",TRUE,TRUE),""\s+$"","""")) & ""?"", IF(M23=""Bold Claim"", ""Fix this in 5 minutes"", IF(M23=""Stop Doing This"", ""Stop struggling with this"", IF(M23=""3 T"&"hings"", ""3 reasons you’ll love this"", ""Best pick for "" & G23)))))"),"Still dealing with bosch drill?") -> Still dealing with bosch drill? | U23: =IF(C23="","","Why it’s worth it: " & E23 & " Features: " & SUBSTITUTE(F23,";"," • ") & ". Great for: " & G23 & ". Keywords: " & H23 & " " & K23) -> Why it’s worth it: Handle precision tasks with this compact cordless drill Features: 12V battery • Compact design • 20-position clutch • LED light • Includes 2 batteries. Great for: precision work and tight spaces. Keywords: Bosch drill, cordless drill, compact drill, 12V drill, power tools, precision tools As an Amazon Associate I earn from qualifying purchases. #ad | V23: =IF(B23="","",IFERROR(VLOOKUP(B23,Boards0!A:B,2,FALSE),"General Finds")) -> Tools That Save Time | W23: =IF(A23="","",TEXT(TODAY(),"yyyy-mm-dd") & "_" & N23 & "_" & A23 & ".png") -> 2026-01-08_T2_PROD022.png
A24: PROD023 | B24: cars | C24: Armor All Car Vacuum Cleaner | D24: Armor All | E24: Keep your car spotless with powerful portable suction | F24: Wet/dry vacuum; 16-foot cord; Multiple attachments; Compact storage; Easy to empty | G24: car owners and detailers | H24: car vacuum, portable vacuum, Armor All, auto cleaning, car accessories, vehicle vacuum | I24: budget | J24: https://www.amazon.com/dp/XXXXXXX?tag=yourtag-20 | K24: As an Amazon Associate I earn from qualifying purchases. #ad | L24: Problem/Solution | M24: Bold Claim | N24: T3 | O24: car | P24: READY | R24: 3 | S24: =IF(C24="","",C24 & " — " & IF(L24="Upgrade","Easy upgrade for ","Best pick for ") & G24) -> Armor All Car Vacuum Cleaner — Best pick for car owners and detailers | T24: =IFERROR(__xludf.DUMMYFUNCTION("IF(C24="""","""",IF(M24=""Question"",""Still dealing with "" & LOWER(REGEXREPLACE(SPLIT(H24,"","",TRUE,TRUE),""\s+$"","""")) & ""?"", IF(M24=""Bold Claim"", ""Fix this in 5 minutes"", IF(M24=""Stop Doing This"", ""Stop struggling with this"", IF(M24=""3 T"&"hings"", ""3 reasons you’ll love this"", ""Best pick for "" & G24)))))"),"Fix this in 5 minutes") -> Fix this in 5 minutes | U24: =IF(C24="","","Why it’s worth it: " & E24 & " Features: " & SUBSTITUTE(F24,";"," • ") & ". Great for: " & G24 & ". Keywords: " & H24 & " " & K24) -> Why it’s worth it: Keep your car spotless with powerful portable suction Features: Wet/dry vacuum • 16-foot cord • Multiple attachments • Compact storage • Easy to empty. Great for: car owners and detailers. Keywords: car vacuum, portable vacuum, Armor All, auto cleaning, car accessories, vehicle vacuum As an Amazon Associate I earn from qualifying purchases. #ad | V24: =IF(B24="","",IFERROR(VLOOKUP(B24,Boards0!A:B,2,FALSE),"General Finds")) -> Car Accessories & Upgrades | W24: =IF(A24="","",TEXT(TODAY(),"yyyy-mm-dd") & "_" & N24 & "_" & A24 & ".png") -> 2026-01-08_T3_PROD023.png
A25: PROD024 | B25: computer accessories | C25: Webcam 1080P HD with Microphone | D25: Logitech | E25: Look professional in video calls with crystal-clear HD quality | F25: 1080P HD; Built-in microphone; Auto light correction; Wide-angle lens; Plug and play | G25: remote workers and streamers | H25: webcam, Logitech webcam, HD camera, video conferencing, streaming camera, computer camera | I25: budget | J25: https://www.amazon.com/dp/XXXXXXX?tag=yourtag-20 | K25: As an Amazon Associate I earn from qualifying purchases. #ad | L25: Upgrade | M25: 3 Things | N25: T4 | O25: clean | P25: READY | R25: 4 | S25: =IF(C25="","",C25 & " — " & IF(L25="Upgrade","Easy upgrade for ","Best pick for ") & G25) -> Webcam 1080P HD with Microphone — Easy upgrade for remote workers and streamers | T25: =IFERROR(__xludf.DUMMYFUNCTION("IF(C25="""","""",IF(M25=""Question"",""Still dealing with "" & LOWER(REGEXREPLACE(SPLIT(H25,"","",TRUE,TRUE),""\s+$"","""")) & ""?"", IF(M25=""Bold Claim"", ""Fix this in 5 minutes"", IF(M25=""Stop Doing This"", ""Stop struggling with this"", IF(M25=""3 T"&"hings"", ""3 reasons you’ll love this"", ""Best pick for "" & G25)))))"),"3 reasons you’ll love this") -> 3 reasons you’ll love this | U25: =IF(C25="","","Why it’s worth it: " & E25 & " Features: " & SUBSTITUTE(F25,";"," • ") & ". Great for: " & G25 & ". Keywords: " & H25 & " " & K25) -> Why it’s worth it: Look professional in video calls with crystal-clear HD quality Features: 1080P HD • Built-in microphone • Auto light correction • Wide-angle lens • Plug and play. Great for: remote workers and streamers. Keywords: webcam, Logitech webcam, HD camera, video conferencing, streaming camera, computer camera As an Amazon Associate I earn from qualifying purchases. #ad | V25: =IF(B25="","",IFERROR(VLOOKUP(B25,Boards0!A:B,2,FALSE),"General Finds")) -> Desk Setup & Accessories | W25: =IF(A25="","",TEXT(TODAY(),"yyyy-mm-dd") & "_" & N25 & "_" & A25 & ".png") -> 2026-01-08_T4_PROD024.png
A26: PROD025 | B26: electronics | C26: Ring Video Doorbell Pro 2 | D26: Ring | E26: See and speak to visitors from anywhere with HD+ video | F26: 1536p HD+ video; 3D motion detection; Two-way talk; Night vision; Alexa compatible | G26: homeowners and security-conscious | H26: Ring doorbell, video doorbell, smart doorbell, home security, Ring camera, doorbell camera | I26: premium | J26: https://www.amazon.com/dp/XXXXXXX?tag=yourtag-20 | K26: As an Amazon Associate I earn from qualifying purchases. #ad | L26: Problem/Solution | M26: Stop Doing This | N26: T5 | O26: tech | P26: READY | R26: 5 | S26: =IF(C26="","",C26 & " — " & IF(L26="Upgrade","Easy upgrade for ","Best pick for ") & G26) -> Ring Video Doorbell Pro 2 — Best pick for homeowners and security-conscious | T26: =IFERROR(__xludf.DUMMYFUNCTION("IF(C26="""","""",IF(M26=""Question"",""Still dealing with "" & LOWER(REGEXREPLACE(SPLIT(H26,"","",TRUE,TRUE),""\s+$"","""")) & ""?"", IF(M26=""Bold Claim"", ""Fix this in 5 minutes"", IF(M26=""Stop Doing This"", ""Stop struggling with this"", IF(M26=""3 T"&"hings"", ""3 reasons you’ll love this"", ""Best pick for "" & G26)))))"),"Stop struggling with this") -> Stop struggling with this | U26: =IF(C26="","","Why it’s worth it: " & E26 & " Features: " & SUBSTITUTE(F26,";"," • ") & ". Great for: " & G26 & ". Keywords: " & H26 & " " & K26) -> Why it’s worth it: See and speak to visitors from anywhere with HD+ video Features: 1536p HD+ video • 3D motion detection • Two-way talk • Night vision • Alexa compatible. Great for: homeowners and security-conscious. Keywords: Ring doorbell, video doorbell, smart doorbell, home security, Ring camera, doorbell camera As an Amazon Associate I earn from qualifying purchases. #ad | V26: =IF(B26="","",IFERROR(VLOOKUP(B26,Boards0!A:B,2,FALSE),"General Finds")) -> Smart Electronics Finds | W26: =IF(A26="","",TEXT(TODAY(),"yyyy-mm-dd") & "_" & N26 & "_" & A26 & ".png") -> 2026-01-08_T5_PROD025.png
A27: PROD026 | B27: home/kitchen | C27: Lodge Cast Iron Skillet 12-Inch | D27: Lodge | E27: Cook like a pro with this pre-seasoned cast iron skillet | F27: Pre-seasoned; 12-inch diameter; Oven safe; Lifetime durability; Even heat distribution | G27: home cooks and camping enthusiasts | H27: cast iron skillet, Lodge, cookware, frying pan, kitchen essentials, camping cookware | I27: budget | J27: https://www.amazon.com/dp/XXXXXXX?tag=yourtag-20 | K27: As an Amazon Associate I earn from qualifying purchases. #ad | L27: Upgrade | M27: Best For | N27: T1 | O27: kitchen | P27: READY | R27: 3 | S27: =IF(C27="","",C27 & " — " & IF(L27="Upgrade","Easy upgrade for ","Best pick for ") & G27) -> Lodge Cast Iron Skillet 12-Inch — Easy upgrade for home cooks and camping enthusiasts | T27: =IFERROR(__xludf.DUMMYFUNCTION("IF(C27="""","""",IF(M27=""Question"",""Still dealing with "" & LOWER(REGEXREPLACE(SPLIT(H27,"","",TRUE,TRUE),""\s+$"","""")) & ""?"", IF(M27=""Bold Claim"", ""Fix this in 5 minutes"", IF(M27=""Stop Doing This"", ""Stop struggling with this"", IF(M27=""3 T"&"hings"", ""3 reasons you’ll love this"", ""Best pick for "" & G27)))))"),"Best pick for home cooks and camping enthusiasts") -> Best pick for home cooks and camping enthusiasts | U27: =IF(C27="","","Why it’s worth it: " & E27 & " Features: " & SUBSTITUTE(F27,";"," • ") & ". Great for: " & G27 & ". Keywords: " & H27 & " " & K27) -> Why it’s worth it: Cook like a pro with this pre-seasoned cast iron skillet Features: Pre-seasoned • 12-inch diameter • Oven safe • Lifetime durability • Even heat distribution. Great for: home cooks and camping enthusiasts. Keywords: cast iron skillet, Lodge, cookware, frying pan, kitchen essentials, camping cookware As an Amazon Associate I earn from qualifying purchases. #ad | V27: =IF(B27="","",IFERROR(VLOOKUP(B27,Boards0!A:B,2,FALSE),"General Finds")) -> Kitchen Upgrades & Must-Haves | W27: =IF(A27="","",TEXT(TODAY(),"yyyy-mm-dd") & "_" & N27 & "_" & A27 & ".png") -> 2026-01-08_T1_PROD026.png
A28: PROD027 | B28: fitness | C28: Foam Roller for Muscle Recovery | D28: TriggerPoint | E28: Speed up recovery and reduce soreness with targeted massage | F28: High-density foam; Multi-density zones; Durable construction; Portable; Includes guide | G28: athletes and fitness enthusiasts | H28: foam roller, muscle recovery, massage roller, fitness recovery, TriggerPoint, workout recovery | I28: budget | J28: https://www.amazon.com/dp/XXXXXXX?tag=yourtag-20 | K28: As an Amazon Associate I earn from qualifying purchases. #ad | L28: Quick Tip | M28: Question | N28: T2 | O28: gym | P28: READY | R28: 3 | S28: =IF(C28="","",C28 & " — " & IF(L28="Upgrade","Easy upgrade for ","Best pick for ") & G28) -> Foam Roller for Muscle Recovery — Best pick for athletes and fitness enthusiasts | T28: =IFERROR(__xludf.DUMMYFUNCTION("IF(C28="""","""",IF(M28=""Question"",""Still dealing with "" & LOWER(REGEXREPLACE(SPLIT(H28,"","",TRUE,TRUE),""\s+$"","""")) & ""?"", IF(M28=""Bold Claim"", ""Fix this in 5 minutes"", IF(M28=""Stop Doing This"", ""Stop struggling with this"", IF(M28=""3 T"&"hings"", ""3 reasons you’ll love this"", ""Best pick for "" & G28)))))"),"Still dealing with foam roller?") -> Still dealing with foam roller? | U28: =IF(C28="","","Why it’s worth it: " & E28 & " Features: " & SUBSTITUTE(F28,";"," • ") & ". Great for: " & G28 & ". Keywords: " & H28 & " " & K28) -> Why it’s worth it: Speed up recovery and reduce soreness with targeted massage Features: High-density foam • Multi-density zones • Durable construction • Portable • Includes guide. Great for: athletes and fitness enthusiasts. Keywords: foam roller, muscle recovery, massage roller, fitness recovery, TriggerPoint, workout recovery As an Amazon Associate I earn from qualifying purchases. #ad | V28: =IF(B28="","",IFERROR(VLOOKUP(B28,Boards0!A:B,2,FALSE),"General Finds")) -> Home Gym Essentials | W28: =IF(A28="","",TEXT(TODAY(),"yyyy-mm-dd") & "_" & N28 & "_" & A28 & ".png") -> 2026-01-08_T2_PROD027.png
A29: PROD028 | B29: tools | C29: Milwaukee M18 Impact Driver Kit | D29: Milwaukee | E29: Drive screws faster with professional-grade impact power | F29: M18 battery system; 1500 in-lbs torque; LED light; Compact; Includes battery and charger | G29: contractors and serious DIYers | H29: impact driver, Milwaukee, power tools, cordless impact, M18 tools, professional tools | I29: premium | J29: https://www.amazon.com/dp/XXXXXXX?tag=yourtag-20 | K29: As an Amazon Associate I earn from qualifying purchases. #ad | L29: Upgrade | M29: Bold Claim | N29: T3 | O29: garage | P29: READY | R29: 5 | S29: =IF(C29="","",C29 & " — " & IF(L29="Upgrade","Easy upgrade for ","Best pick for ") & G29) -> Milwaukee M18 Impact Driver Kit — Easy upgrade for contractors and serious DIYers | T29: =IFERROR(__xludf.DUMMYFUNCTION("IF(C29="""","""",IF(M29=""Question"",""Still dealing with "" & LOWER(REGEXREPLACE(SPLIT(H29,"","",TRUE,TRUE),""\s+$"","""")) & ""?"", IF(M29=""Bold Claim"", ""Fix this in 5 minutes"", IF(M29=""Stop Doing This"", ""Stop struggling with this"", IF(M29=""3 T"&"hings"", ""3 reasons you’ll love this"", ""Best pick for "" & G29)))))"),"Fix this in 5 minutes") -> Fix this in 5 minutes | U29: =IF(C29="","","Why it’s worth it: " & E29 & " Features: " & SUBSTITUTE(F29,";"," • ") & ". Great for: " & G29 & ". Keywords: " & H29 & " " & K29) -> Why it’s worth it: Drive screws faster with professional-grade impact power Features: M18 battery system • 1500 in-lbs torque • LED light • Compact • Includes battery and charger. Great for: contractors and serious DIYers. Keywords: impact driver, Milwaukee, power tools, cordless impact, M18 tools, professional tools As an Amazon Associate I earn from qualifying purchases. #ad | V29: =IF(B29="","",IFERROR(VLOOKUP(B29,Boards0!A:B,2,FALSE),"General Finds")) -> Tools That Save Time | W29: =IF(A29="","",TEXT(TODAY(),"yyyy-mm-dd") & "_" & N29 & "_" & A29 & ".png") -> 2026-01-08_T3_PROD028.png
A30: PROD029 | B30: cars | C30: Michelin Stealth Hybrid Wiper Blades | D30: Michelin | E30: See clearly in any weather with premium wiper blades | F30: Hybrid design; All-weather performance; Easy installation; Quiet operation; Durable | G30: all car owners | H30: wiper blades, Michelin, car parts, windshield wipers, auto accessories, all-weather wipers | I30: budget | J30: https://www.amazon.com/dp/XXXXXXX?tag=yourtag-20 | K30: As an Amazon Associate I earn from qualifying purchases. #ad | L30: Problem/Solution | M30: 3 Things | N30: T4 | O30: car | P30: READY | R30: 3 | S30: =IF(C30="","",C30 & " — " & IF(L30="Upgrade","Easy upgrade for ","Best pick for ") & G30) -> Michelin Stealth Hybrid Wiper Blades — Best pick for all car owners | T30: =IFERROR(__xludf.DUMMYFUNCTION("IF(C30="""","""",IF(M30=""Question"",""Still dealing with "" & LOWER(REGEXREPLACE(SPLIT(H30,"","",TRUE,TRUE),""\s+$"","""")) & ""?"", IF(M30=""Bold Claim"", ""Fix this in 5 minutes"", IF(M30=""Stop Doing This"", ""Stop struggling with this"", IF(M30=""3 T"&"hings"", ""3 reasons you’ll love this"", ""Best pick for "" & G30)))))"),"3 reasons you’ll love this") -> 3 reasons you’ll love this | U30: =IF(C30="","","Why it’s worth it: " & E30 & " Features: " & SUBSTITUTE(F30,";"," • ") & ". Great for: " & G30 & ". Keywords: " & H30 & " " & K30) -> Why it’s worth it: See clearly in any weather with premium wiper blades Features: Hybrid design • All-weather performance • Easy installation • Quiet operation • Durable. Great for: all car owners. Keywords: wiper blades, Michelin, car parts, windshield wipers, auto accessories, all-weather wipers As an Amazon Associate I earn from qualifying purchases. #ad | V30: =IF(B30="","",IFERROR(VLOOKUP(B30,Boards0!A:B,2,FALSE),"General Finds")) -> Car Accessories & Upgrades | W30: =IF(A30="","",TEXT(TODAY(),"yyyy-mm-dd") & "_" & N30 & "_" & A30 & ".png") -> 2026-01-08_T4_PROD029.png
